<?xml version='1.0'?>
<robot name="quadrus" xmlns:xacro="http://www.ros.org/wiki/xacro">

	<!-- Import Rviz colors -->
	<xacro:include filename="$(find qd_simulation)/robot_description/materials.xacro" />
	
    <!-- Import all Gazebo-customization elements, including Gazebo colors -->
	<xacro:include filename="$(find qd_simulation)/robot_description/quadrus.gazebo" />

	<!-- Used for fixing robot to Gazebo 'base_link' -->
	<link name="world"/>

	<link name="base_link">
		<visual>
			<origin xyz="0 0 0.25" rpy="0 0 0" />
			<geometry>
				<box size="0.1 0.1 0.5"/>
			</geometry>
			<material name="blue" />
		</visual>

        <inertial>
            <origin xyz="0 0 0"/>
            <mass value="0.15"/>
            <inertia ixx="0.0" ixy="0.0" ixz="0.0" iyy="0.0" iyz="0.0" izz="0.0"/>
        </inertial>

	</link>

    <link name="baton">
        <visual>
            <origin xyz="0.075 0 0" rpy="0 0 0" />
            <geometry>
                <box size="0.175 0.025 0.00635"/>
            </geometry>
            <material name="blue"/>
        </visual>      

        <inertial>
            <origin xyz="0.0875 0 0"/>
            <mass value="0.015"/>
            <inertia ixx="0.0" ixy="0.0" ixz="0.0" iyy="0.0" iyz="0.0" izz="0.000039062"/>
        </inertial>

    </link>

    <link name="masse">
       <visual>
            <origin xyz="0 0 0.004175" rpy="0 0 0" />
            <geometry>
                <cylinder radius="0.025" length="0.008"/>
            </geometry>
            <material name="blue"/>
        </visual>        

        <inertial>
            <origin xyz="0 0 0"/>
            <mass value="0.163"/>
            <inertia ixx="0.0" ixy="0.0" ixz="0.0" iyy="0.0" iyz="0.0" izz="0.000050625"/>
        </inertial>

    </link>


	<joint name="fixed" type="fixed">
		<parent link="world"/>
		<child link="base_link"/>
		<origin xyz="0 0 0"/>
	</joint>

    <joint name="J1" type="continuous">
        <parent link="base_link"/>
        <child link="baton"/>
        <origin xyz="0 0.06 0.45" rpy="-1.570 1.57 0" /> 
        <axis xyz="0 0 1" />
    </joint>

    <joint name="fixed2" type="fixed">
        <parent link="baton"/>
        <child link="masse"/>
        <origin xyz="0.1375 0 0" rpy="0 0 0" /> 
        <axis xyz="0 0 0" />
    </joint>

    <transmission name="transmission_J1">
        <type>transmission_interface/SimpleTransmission</type>

        <joint name="J1">
            <hardwareInterface>hardware_interface/EffortJointInterface</hardwareInterface>
        </joint>

        <actuator name="motor_J1">
            <mechanicalReduction>1</mechanicalReduction>
            <hardwareInterface>hardware_interface/EffortJointInterface</hardwareInterface>
        </actuator>

    </transmission>

</robot>
