<?xml version="1.0" ?>
<!-- =================================================================================== -->
<!-- |    This document was autogenerated by xacro from quadrus.xacro                  | -->
<!-- |    EDITING THIS FILE BY HAND IS NOT RECOMMENDED                                 | -->
<!-- =================================================================================== -->
<robot name="quadrus">
  <material name="black">
    <color rgba="0.0 0.0 0.0 1.0"/>
  </material>
  <material name="blue">
    <color rgba="0.0 0.0 0.8 1.0"/>
  </material>
  <material name="green">
    <color rgba="0.0 0.8 0.0 1.0"/>
  </material>
  <material name="grey">
    <color rgba="0.2 0.2 0.2 1.0"/>
  </material>
  <material name="orange">
    <color rgba="1.0 0.4235294117647059 0.0392156862745098 1.0"/>
  </material>
  <material name="brown">
    <color rgba="0.8705882352941177 0.8117647058823529 0.7647058823529411 1.0"/>
  </material>
  <material name="red">
    <color rgba="0.8 0.0 0.0 1.0"/>
  </material>
  <material name="white">
    <color rgba="1.0 1.0 1.0 1.0"/>
  </material>
  <!-- ros_control plugin -->
  <gazebo>
    <plugin filename="libgazebo_ros_control.so" name="gazebo_ros_control">
      <robotNamespace>/quadrus</robotNamespace>
      <robotSimType>gazebo_ros_control/DefaultRobotHWSim</robotSimType>
    </plugin>
  </gazebo>
  <gazebo reference="base_link">
    <material>Gazebo/Blue</material>
    <pose>0 0 1 0 0 0 </pose>
  </gazebo>
  <!-- Used for fixing robot to Gazebo 'base_link' -->
  <link name="world"/>
  <joint name="fixed" type="fixed">
    <parent link="world"/>
    <child link="base_link"/>
    <origin xyz="0 0 1"/>
  </joint>
  <link name="base_link">
    <visual>
      <origin rpy="0 0 0" xyz="0 0 0"/>
      <geometry>
        <box size="0.30 0.10 0.07"/>
      </geometry>
      <material name="blue"/>
    </visual>
    <visual>
      <origin rpy="0 0 0" xyz="0 0 0"/>
      <geometry>
        <box size="0.2 0.18 0.07"/>
      </geometry>
      <material name="blue"/>
    </visual>
    <collision>
      <origin rpy="0 0 0" xyz="0 0 0"/>
      <geometry>
        <box size="0.30 0.10 0.07"/>
      </geometry>
    </collision>
    <inertial>
      <mass value="2"/>
      <inertia ixx="0.13" ixy="0.0" ixz="0.0" iyy="0.21" iyz="0.0" izz="0.13"/>
    </inertial>
  </link>
  <!-- Hip -->
  <link name="link_back_right_hip">
    <visual>
      <origin rpy="0 0 0" xyz="0 0 0"/>
      <geometry>
        <box size="0.03 0.05 0.03"/>
      </geometry>
      <material name="red"/>
    </visual>
    <collision>
      <origin rpy="0 0 0" xyz="0 0 0"/>
      <geometry>
        <box size="0.03 0.05 0.03"/>
      </geometry>
    </collision>
    <inertial>
      <mass value="0.1"/>
      <inertia ixx="0.01" ixy="0.0" ixz="0.0" iyy="0.01" iyz="0.0" izz="0.01"/>
    </inertial>
  </link>
  <joint name="joint_back_right_hip" type="continuous">
    <parent link="base_link"/>
    <child link="link_back_right_hip"/>
    <origin rpy="0 0 0" xyz="-0.12 -0.075 0"/>
    <axis xyz="1 0 0"/>
  </joint>
  <transmission name="transmission_back_right_hip">
    <type>transmission_interface/SimpleTransmission</type>
    <joint name="joint_back_right_hip">
      <hardwareInterface>hardware_interface/EffortJointInterface</hardwareInterface>
    </joint>
    <actuator name="motor_back_right_hip">
      <mechanicalReduction>1</mechanicalReduction>
      <hardwareInterface>hardware_interface/EffortJointInterface</hardwareInterface>
    </actuator>
  </transmission>
  <gazebo reference="link_back_right_hip">
    <material>Gazebo/Red</material>
  </gazebo>
  <!-- Upperleg -->
  <link name="link_back_right_upperleg">
    <visual>
      <origin rpy="0 0 0" xyz="-0.075 0 0"/>
      <geometry>
        <box size="0.18 0.03 0.03"/>
      </geometry>
      <material name="blue"/>
    </visual>
    <collision>
      <origin rpy="0 0 0" xyz="-0.075 0 0"/>
      <geometry>
        <box size="0.18 0.03 0.03"/>
      </geometry>
    </collision>
    <inertial>
      <mass value="0.1"/>
      <inertia ixx="0.1" ixy="0.0" ixz="0.0" iyy="0.1" iyz="0.0" izz="0.1"/>
    </inertial>
  </link>
  <joint name="joint_back_right_upperleg" type="continuous">
    <parent link="link_back_right_hip"/>
    <child link="link_back_right_upperleg"/>
    <origin rpy="0 -0.7854 0" xyz="0 -0.04 0"/>
    <axis xyz="0 1 0"/>
  </joint>
  <transmission name="transmission_back_right_upperleg">
    <type>transmission_interface/SimpleTransmission</type>
    <joint name="joint_back_right_upperleg">
      <hardwareInterface>hardware_interface/EffortJointInterface</hardwareInterface>
    </joint>
    <actuator name="motor_back_right_upperleg">
      <mechanicalReduction>1</mechanicalReduction>
      <hardwareInterface>hardware_interface/EffortJointInterface</hardwareInterface>
    </actuator>
  </transmission>
  <gazebo reference="link_back_right_upperleg">
    <material>Gazebo/White</material>
  </gazebo>
  <!-- LowerLeg -->
  <link name="link_back_right_lowerleg">
    <visual>
      <origin rpy="0 0 0" xyz="0.075 0 0"/>
      <geometry>
        <box size="0.18 0.03 0.03"/>
      </geometry>
      <material name="blue"/>
    </visual>
    <collision>
      <origin rpy="0 0 0" xyz="0.075 0 0"/>
      <geometry>
        <box size="0.18 0.03 0.03"/>
      </geometry>
    </collision>
    <inertial>
      <mass value="0.1"/>
      <inertia ixx="0.1" ixy="0.0" ixz="0.0" iyy="0.1" iyz="0.0" izz="0.1"/>
    </inertial>
  </link>
  <joint name="joint_back_right_lowerleg" type="continuous">
    <parent link="link_back_right_upperleg"/>
    <child link="link_back_right_lowerleg"/>
    <origin rpy="0 1.5708 0" xyz="-0.15 0 0"/>
    <axis xyz="0 1 0"/>
  </joint>
  <transmission name="transmission_back_right_lowerleg">
    <type>transmission_interface/SimpleTransmission</type>
    <joint name="joint_back_right_lowerleg">
      <hardwareInterface>hardware_interface/EffortJointInterface</hardwareInterface>
    </joint>
    <actuator name="motor_back_right_lowerleg">
      <mechanicalReduction>1</mechanicalReduction>
      <hardwareInterface>hardware_interface/EffortJointInterface</hardwareInterface>
    </actuator>
  </transmission>
  <gazebo reference="link_back_right_lowerleg">
    <material>Gazebo/White</material>
  </gazebo>
  <!-- Paw -->
  <link name="link_back_right_paw">
    <visual>
      <origin rpy="0 0 0" xyz="0 0 0"/>
      <geometry>
        <sphere radius="0.03"/>
      </geometry>
      <material name="green"/>
    </visual>
    <collision>
      <origin rpy="0 0 0" xyz="0 0 0"/>
      <geometry>
        <sphere radius="0.03"/>
      </geometry>
    </collision>
    <inertial>
      <mass value="0.1"/>
      <inertia ixx="0.1" ixy="0.0" ixz="0.0" iyy="0.1" iyz="0.0" izz="0.1"/>
    </inertial>
  </link>
  <joint name="joint_back_right_paw" type="fixed">
    <parent link="link_back_right_lowerleg"/>
    <child link="link_back_right_paw"/>
    <origin rpy="0 0 0" xyz="0.15 0 0"/>
  </joint>
  <gazebo reference="link_back_right_paw">
    <material>Gazebo/Green</material>
  </gazebo>
  <!-- Hip -->
  <link name="link_back_left_hip">
    <visual>
      <origin rpy="0 0 0" xyz="0 0 0"/>
      <geometry>
        <box size="0.03 0.05 0.03"/>
      </geometry>
      <material name="red"/>
    </visual>
    <collision>
      <origin rpy="0 0 0" xyz="0 0 0"/>
      <geometry>
        <box size="0.03 0.05 0.03"/>
      </geometry>
    </collision>
    <inertial>
      <mass value="0.1"/>
      <inertia ixx="0.01" ixy="0.0" ixz="0.0" iyy="0.01" iyz="0.0" izz="0.01"/>
    </inertial>
  </link>
  <joint name="joint_back_left_hip" type="continuous">
    <parent link="base_link"/>
    <child link="link_back_left_hip"/>
    <origin rpy="0 0 0" xyz="-0.12 0.075 0"/>
    <axis xyz="1 0 0"/>
  </joint>
  <transmission name="transmission_back_left_hip">
    <type>transmission_interface/SimpleTransmission</type>
    <joint name="joint_back_left_hip">
      <hardwareInterface>hardware_interface/EffortJointInterface</hardwareInterface>
    </joint>
    <actuator name="motor_back_left_hip">
      <mechanicalReduction>1</mechanicalReduction>
      <hardwareInterface>hardware_interface/EffortJointInterface</hardwareInterface>
    </actuator>
  </transmission>
  <gazebo reference="link_back_left_hip">
    <material>Gazebo/Red</material>
  </gazebo>
  <!-- Upperleg -->
  <link name="link_back_left_upperleg">
    <visual>
      <origin rpy="0 0 0" xyz="-0.075 0 0"/>
      <geometry>
        <box size="0.18 0.03 0.03"/>
      </geometry>
      <material name="blue"/>
    </visual>
    <collision>
      <origin rpy="0 0 0" xyz="-0.075 0 0"/>
      <geometry>
        <box size="0.18 0.03 0.03"/>
      </geometry>
    </collision>
    <inertial>
      <mass value="0.1"/>
      <inertia ixx="0.1" ixy="0.0" ixz="0.0" iyy="0.1" iyz="0.0" izz="0.1"/>
    </inertial>
  </link>
  <joint name="joint_back_left_upperleg" type="continuous">
    <parent link="link_back_left_hip"/>
    <child link="link_back_left_upperleg"/>
    <origin rpy="0 -0.7854 0" xyz="0 0.04 0"/>
    <axis xyz="0 1 0"/>
  </joint>
  <transmission name="transmission_back_left_upperleg">
    <type>transmission_interface/SimpleTransmission</type>
    <joint name="joint_back_left_upperleg">
      <hardwareInterface>hardware_interface/EffortJointInterface</hardwareInterface>
    </joint>
    <actuator name="motor_back_left_upperleg">
      <mechanicalReduction>1</mechanicalReduction>
      <hardwareInterface>hardware_interface/EffortJointInterface</hardwareInterface>
    </actuator>
  </transmission>
  <gazebo reference="link_back_left_upperleg">
    <material>Gazebo/White</material>
  </gazebo>
  <!-- LowerLeg -->
  <link name="link_back_left_lowerleg">
    <visual>
      <origin rpy="0 0 0" xyz="0.075 0 0"/>
      <geometry>
        <box size="0.18 0.03 0.03"/>
      </geometry>
      <material name="blue"/>
    </visual>
    <collision>
      <origin rpy="0 0 0" xyz="0.075 0 0"/>
      <geometry>
        <box size="0.18 0.03 0.03"/>
      </geometry>
    </collision>
    <inertial>
      <mass value="0.1"/>
      <inertia ixx="0.1" ixy="0.0" ixz="0.0" iyy="0.1" iyz="0.0" izz="0.1"/>
    </inertial>
  </link>
  <joint name="joint_back_left_lowerleg" type="continuous">
    <parent link="link_back_left_upperleg"/>
    <child link="link_back_left_lowerleg"/>
    <origin rpy="0 1.5708 0" xyz="-0.15 0 0"/>
    <axis xyz="0 1 0"/>
  </joint>
  <transmission name="transmission_back_left_lowerleg">
    <type>transmission_interface/SimpleTransmission</type>
    <joint name="joint_back_left_lowerleg">
      <hardwareInterface>hardware_interface/EffortJointInterface</hardwareInterface>
    </joint>
    <actuator name="motor_back_left_lowerleg">
      <mechanicalReduction>1</mechanicalReduction>
      <hardwareInterface>hardware_interface/EffortJointInterface</hardwareInterface>
    </actuator>
  </transmission>
  <gazebo reference="link_back_left_lowerleg">
    <material>Gazebo/White</material>
  </gazebo>
  <!-- Paw -->
  <link name="link_back_left_paw">
    <visual>
      <origin rpy="0 0 0" xyz="0 0 0"/>
      <geometry>
        <sphere radius="0.03"/>
      </geometry>
      <material name="green"/>
    </visual>
    <collision>
      <origin rpy="0 0 0" xyz="0 0 0"/>
      <geometry>
        <sphere radius="0.03"/>
      </geometry>
    </collision>
    <inertial>
      <mass value="0.1"/>
      <inertia ixx="0.1" ixy="0.0" ixz="0.0" iyy="0.1" iyz="0.0" izz="0.1"/>
    </inertial>
  </link>
  <joint name="joint_back_left_paw" type="fixed">
    <parent link="link_back_left_lowerleg"/>
    <child link="link_back_left_paw"/>
    <origin rpy="0 0 0" xyz="0.15 0 0"/>
  </joint>
  <gazebo reference="link_back_left_paw">
    <material>Gazebo/Green</material>
  </gazebo>
  <!-- Hip -->
  <link name="link_front_right_hip">
    <visual>
      <origin rpy="0 0 0" xyz="0 0 0"/>
      <geometry>
        <box size="0.03 0.05 0.03"/>
      </geometry>
      <material name="red"/>
    </visual>
    <collision>
      <origin rpy="0 0 0" xyz="0 0 0"/>
      <geometry>
        <box size="0.03 0.05 0.03"/>
      </geometry>
    </collision>
    <inertial>
      <mass value="0.1"/>
      <inertia ixx="0.01" ixy="0.0" ixz="0.0" iyy="0.01" iyz="0.0" izz="0.01"/>
    </inertial>
  </link>
  <joint name="joint_front_right_hip" type="continuous">
    <parent link="base_link"/>
    <child link="link_front_right_hip"/>
    <origin rpy="0 0 0" xyz="0.12 -0.075 0"/>
    <axis xyz="1 0 0"/>
  </joint>
  <transmission name="transmission_front_right_hip">
    <type>transmission_interface/SimpleTransmission</type>
    <joint name="joint_front_right_hip">
      <hardwareInterface>hardware_interface/EffortJointInterface</hardwareInterface>
    </joint>
    <actuator name="motor_front_right_hip">
      <mechanicalReduction>1</mechanicalReduction>
      <hardwareInterface>hardware_interface/EffortJointInterface</hardwareInterface>
    </actuator>
  </transmission>
  <gazebo reference="link_front_right_hip">
    <material>Gazebo/Red</material>
  </gazebo>
  <!-- Upperleg -->
  <link name="link_front_right_upperleg">
    <visual>
      <origin rpy="0 0 0" xyz="-0.075 0 0"/>
      <geometry>
        <box size="0.18 0.03 0.03"/>
      </geometry>
      <material name="blue"/>
    </visual>
    <collision>
      <origin rpy="0 0 0" xyz="-0.075 0 0"/>
      <geometry>
        <box size="0.18 0.03 0.03"/>
      </geometry>
    </collision>
    <inertial>
      <mass value="0.1"/>
      <inertia ixx="0.1" ixy="0.0" ixz="0.0" iyy="0.1" iyz="0.0" izz="0.1"/>
    </inertial>
  </link>
  <joint name="joint_front_right_upperleg" type="continuous">
    <parent link="link_front_right_hip"/>
    <child link="link_front_right_upperleg"/>
    <origin rpy="0 -0.7854 0" xyz="0 -0.04 0"/>
    <axis xyz="0 1 0"/>
  </joint>
  <transmission name="transmission_front_right_upperleg">
    <type>transmission_interface/SimpleTransmission</type>
    <joint name="joint_front_right_upperleg">
      <hardwareInterface>hardware_interface/EffortJointInterface</hardwareInterface>
    </joint>
    <actuator name="motor_front_right_upperleg">
      <mechanicalReduction>1</mechanicalReduction>
      <hardwareInterface>hardware_interface/EffortJointInterface</hardwareInterface>
    </actuator>
  </transmission>
  <gazebo reference="link_front_right_upperleg">
    <material>Gazebo/White</material>
  </gazebo>
  <!-- LowerLeg -->
  <link name="link_front_right_lowerleg">
    <visual>
      <origin rpy="0 0 0" xyz="0.075 0 0"/>
      <geometry>
        <box size="0.18 0.03 0.03"/>
      </geometry>
      <material name="blue"/>
    </visual>
    <collision>
      <origin rpy="0 0 0" xyz="0.075 0 0"/>
      <geometry>
        <box size="0.18 0.03 0.03"/>
      </geometry>
    </collision>
    <inertial>
      <mass value="0.1"/>
      <inertia ixx="0.1" ixy="0.0" ixz="0.0" iyy="0.1" iyz="0.0" izz="0.1"/>
    </inertial>
  </link>
  <joint name="joint_front_right_lowerleg" type="continuous">
    <parent link="link_front_right_upperleg"/>
    <child link="link_front_right_lowerleg"/>
    <origin rpy="0 1.5708 0" xyz="-0.15 0 0"/>
    <axis xyz="0 1 0"/>
  </joint>
  <transmission name="transmission_front_right_lowerleg">
    <type>transmission_interface/SimpleTransmission</type>
    <joint name="joint_front_right_lowerleg">
      <hardwareInterface>hardware_interface/EffortJointInterface</hardwareInterface>
    </joint>
    <actuator name="motor_front_right_lowerleg">
      <mechanicalReduction>1</mechanicalReduction>
      <hardwareInterface>hardware_interface/EffortJointInterface</hardwareInterface>
    </actuator>
  </transmission>
  <gazebo reference="link_front_right_lowerleg">
    <material>Gazebo/White</material>
  </gazebo>
  <!-- Paw -->
  <link name="link_front_right_paw">
    <visual>
      <origin rpy="0 0 0" xyz="0 0 0"/>
      <geometry>
        <sphere radius="0.03"/>
      </geometry>
      <material name="green"/>
    </visual>
    <collision>
      <origin rpy="0 0 0" xyz="0 0 0"/>
      <geometry>
        <sphere radius="0.03"/>
      </geometry>
    </collision>
    <inertial>
      <mass value="0.1"/>
      <inertia ixx="0.1" ixy="0.0" ixz="0.0" iyy="0.1" iyz="0.0" izz="0.1"/>
    </inertial>
  </link>
  <joint name="joint_front_right_paw" type="fixed">
    <parent link="link_front_right_lowerleg"/>
    <child link="link_front_right_paw"/>
    <origin rpy="0 0 0" xyz="0.15 0 0"/>
  </joint>
  <gazebo reference="link_front_right_paw">
    <material>Gazebo/Green</material>
  </gazebo>
  <!-- Hip -->
  <link name="link_front_left_hip">
    <visual>
      <origin rpy="0 0 0" xyz="0 0 0"/>
      <geometry>
        <box size="0.03 0.05 0.03"/>
      </geometry>
      <material name="red"/>
    </visual>
    <collision>
      <origin rpy="0 0 0" xyz="0 0 0"/>
      <geometry>
        <box size="0.03 0.05 0.03"/>
      </geometry>
    </collision>
    <inertial>
      <mass value="0.1"/>
      <inertia ixx="0.01" ixy="0.0" ixz="0.0" iyy="0.01" iyz="0.0" izz="0.01"/>
    </inertial>
  </link>
  <joint name="joint_front_left_hip" type="continuous">
    <parent link="base_link"/>
    <child link="link_front_left_hip"/>
    <origin rpy="0 0 0" xyz="0.12 0.075 0"/>
    <axis xyz="1 0 0"/>
  </joint>
  <transmission name="transmission_front_left_hip">
    <type>transmission_interface/SimpleTransmission</type>
    <joint name="joint_front_left_hip">
      <hardwareInterface>hardware_interface/EffortJointInterface</hardwareInterface>
    </joint>
    <actuator name="motor_front_left_hip">
      <mechanicalReduction>1</mechanicalReduction>
      <hardwareInterface>hardware_interface/EffortJointInterface</hardwareInterface>
    </actuator>
  </transmission>
  <gazebo reference="link_front_left_hip">
    <material>Gazebo/Red</material>
  </gazebo>
  <!-- Upperleg -->
  <link name="link_front_left_upperleg">
    <visual>
      <origin rpy="0 0 0" xyz="-0.075 0 0"/>
      <geometry>
        <box size="0.18 0.03 0.03"/>
      </geometry>
      <material name="blue"/>
    </visual>
    <collision>
      <origin rpy="0 0 0" xyz="-0.075 0 0"/>
      <geometry>
        <box size="0.18 0.03 0.03"/>
      </geometry>
    </collision>
    <inertial>
      <mass value="0.1"/>
      <inertia ixx="0.1" ixy="0.0" ixz="0.0" iyy="0.1" iyz="0.0" izz="0.1"/>
    </inertial>
  </link>
  <joint name="joint_front_left_upperleg" type="continuous">
    <parent link="link_front_left_hip"/>
    <child link="link_front_left_upperleg"/>
    <origin rpy="0 -0.7854 0" xyz="0 0.04 0"/>
    <axis xyz="0 1 0"/>
  </joint>
  <transmission name="transmission_front_left_upperleg">
    <type>transmission_interface/SimpleTransmission</type>
    <joint name="joint_front_left_upperleg">
      <hardwareInterface>hardware_interface/EffortJointInterface</hardwareInterface>
    </joint>
    <actuator name="motor_front_left_upperleg">
      <mechanicalReduction>1</mechanicalReduction>
      <hardwareInterface>hardware_interface/EffortJointInterface</hardwareInterface>
    </actuator>
  </transmission>
  <gazebo reference="link_front_left_upperleg">
    <material>Gazebo/White</material>
  </gazebo>
  <!-- LowerLeg -->
  <link name="link_front_left_lowerleg">
    <visual>
      <origin rpy="0 0 0" xyz="0.075 0 0"/>
      <geometry>
        <box size="0.18 0.03 0.03"/>
      </geometry>
      <material name="blue"/>
    </visual>
    <collision>
      <origin rpy="0 0 0" xyz="0.075 0 0"/>
      <geometry>
        <box size="0.18 0.03 0.03"/>
      </geometry>
    </collision>
    <inertial>
      <mass value="0.1"/>
      <inertia ixx="0.1" ixy="0.0" ixz="0.0" iyy="0.1" iyz="0.0" izz="0.1"/>
    </inertial>
  </link>
  <joint name="joint_front_left_lowerleg" type="continuous">
    <parent link="link_front_left_upperleg"/>
    <child link="link_front_left_lowerleg"/>
    <origin rpy="0 1.5708 0" xyz="-0.15 0 0"/>
    <axis xyz="0 1 0"/>
  </joint>
  <transmission name="transmission_front_left_lowerleg">
    <type>transmission_interface/SimpleTransmission</type>
    <joint name="joint_front_left_lowerleg">
      <hardwareInterface>hardware_interface/EffortJointInterface</hardwareInterface>
    </joint>
    <actuator name="motor_front_left_lowerleg">
      <mechanicalReduction>1</mechanicalReduction>
      <hardwareInterface>hardware_interface/EffortJointInterface</hardwareInterface>
    </actuator>
  </transmission>
  <gazebo reference="link_front_left_lowerleg">
    <material>Gazebo/White</material>
  </gazebo>
  <!-- Paw -->
  <link name="link_front_left_paw">
    <visual>
      <origin rpy="0 0 0" xyz="0 0 0"/>
      <geometry>
        <sphere radius="0.03"/>
      </geometry>
      <material name="green"/>
    </visual>
    <collision>
      <origin rpy="0 0 0" xyz="0 0 0"/>
      <geometry>
        <sphere radius="0.03"/>
      </geometry>
    </collision>
    <inertial>
      <mass value="0.1"/>
      <inertia ixx="0.1" ixy="0.0" ixz="0.0" iyy="0.1" iyz="0.0" izz="0.1"/>
    </inertial>
  </link>
  <joint name="joint_front_left_paw" type="fixed">
    <parent link="link_front_left_lowerleg"/>
    <child link="link_front_left_paw"/>
    <origin rpy="0 0 0" xyz="0.15 0 0"/>
  </joint>
  <gazebo reference="link_front_left_paw">
    <material>Gazebo/Green</material>
  </gazebo>
</robot>

