<?xml version="1.0" ?>
<!-- =================================================================================== -->
<!-- |    This document was autogenerated by xacro from quadrus.xacro                  | -->
<!-- |    EDITING THIS FILE BY HAND IS NOT RECOMMENDED                                 | -->
<!-- =================================================================================== -->
<robot name="quadrus">
  <material name="black">
    <color rgba="0.0 0.0 0.0 1.0"/>
  </material>
  <material name="blue">
    <color rgba="0.0 0.0 0.8 1.0"/>
  </material>
  <material name="green">
    <color rgba="0.0 0.8 0.0 1.0"/>
  </material>
  <material name="grey">
    <color rgba="0.2 0.2 0.2 1.0"/>
  </material>
  <material name="orange">
    <color rgba="1.0 0.4235294117647059 0.0392156862745098 1.0"/>
  </material>
  <material name="brown">
    <color rgba="0.8705882352941177 0.8117647058823529 0.7647058823529411 1.0"/>
  </material>
  <material name="red">
    <color rgba="0.8 0.0 0.0 1.0"/>
  </material>
  <material name="white">
    <color rgba="1.0 1.0 1.0 1.0"/>
  </material>
  <!-- ros_control plugin -->
  <gazebo>
    <plugin filename="libgazebo_ros_control.so" name="gazebo_ros_control">
      <robotNamespace>/quadrus</robotNamespace>
      <robotSimType>gazebo_ros_control/DefaultRobotHWSim</robotSimType>
    </plugin>
  </gazebo>
  <!-- Used for fixing robot to Gazebo's base link -->
  <link name="base_link"/>
  <joint name="floating" type="fixed">
    <parent link="base_link"/>
    <child link="chassis"/>
    <origin xyz="0 0 0"/>
  </joint>
  <!-- Chassis -->
  <link name="chassis">
    <visual>
      <origin rpy="0 0 0" xyz="0 0 0"/>
      <geometry>
        <mesh filename="package://qd_simulation/robot_description/mesh/body.dae"/>
      </geometry>
      <material name="blue"/>
    </visual>
    <collision>
      <origin rpy="0 0 0" xyz="0 0 0"/>
      <geometry>
        <box size="0.4172 0.136 0.03"/>
        <!-- mesh filename="package://qd_simulation/robot_description/mesh/body.dae"/-->
      </geometry>
    </collision>
    <inertial>
      <mass value="0.97859"/>
      <origin xyz="-0.01428 0.00536 -0.00018"/>
      <inertia ixx="0.00307" ixy="-0.00006" ixz="0.00006" iyy="0.01728" iyz="0.00003" izz="0.02001"/>
    </inertial>
  </link>
  <gazebo reference="chassis">
    <material>Gazebo/Blue</material>
    <gravity>true</gravity>
  </gazebo>
  <link name="link_front_left_hip">
    <visual>
      <origin rpy="0 0 0" xyz="0 0 0"/>
      <geometry>
        <mesh filename="package://qd_simulation/robot_description/mesh/left_hip.dae"/>
      </geometry>
      <material name="red"/>
    </visual>
    <collision>
      <origin rpy="0 0 0" xyz="0.014 0.04125 0.0147"/>
      <geometry>
        <box size="0.064 0.103 0.0685"/>
        <!-- mesh filename="package://qd_simulation/robot_description/mesh/left_hip.dae"/-->
      </geometry>
    </collision>
    <inertial>
      <mass value="0.1191"/>
      <origin xyz="0.00364 0.0025 0.01974"/>
      <inertia ixx="0.000176" ixy="-0.000004" ixz="-0.000017" iyy="0.000131" iyz="-0.000021" izz="0.000108"/>
    </inertial>
  </link>
  <joint name="J1" type="revolute">
    <parent link="chassis"/>
    <child link="link_front_left_hip"/>
    <origin rpy="0 0 0" xyz="0.12 0.089 0"/>
    <limit effort="30" lower="-0.401" upper="0.785" velocity="10"/>
    <axis xyz="1 0 0"/>
  </joint>
  <transmission name="transmission_front_left_hip">
    <type>transmission_interface/SimpleTransmission</type>
    <joint name="J1">
      <hardwareInterface>hardware_interface/EffortJointInterface</hardwareInterface>
    </joint>
    <actuator name="motor_front_left_hip">
      <mechanicalReduction>1</mechanicalReduction>
      <hardwareInterface>hardware_interface/EffortJointInterface</hardwareInterface>
    </actuator>
  </transmission>
  <gazebo reference="link_front_left_hip">
    <material>Gazebo/Red</material>
    <!-- selfCollide>true</selfCollide -->
    <gravity>true</gravity>
  </gazebo>
  <link name="link_front_left_upperleg">
    <visual>
      <origin rpy="0 0 0" xyz="0 0 0"/>
      <geometry>
        <mesh filename="package://qd_simulation/robot_description/mesh/left_femur.dae"/>
      </geometry>
      <material name="blue"/>
    </visual>
    <collision>
      <origin rpy="0 0 0" xyz="-0.066 0 -0.008"/>
      <geometry>
        <box size="0.172 0.073 0.046"/>
        <!-- mesh filename="package://qd_simulation/robot_description/mesh/left_femur.dae"/-->
      </geometry>
    </collision>
    <inertial>
      <mass value="0.13118"/>
      <origin xyz="-0.041697 -0.007043 -0.000214"/>
      <inertia ixx="0.000042" ixy="-0.000009" ixz="0.000011" iyy="0.000283" iyz="0.000002" izz="0.000310"/>
    </inertial>
  </link>
  <joint name="J2" type="revolute">
    <parent link="link_front_left_hip"/>
    <child link="link_front_left_upperleg"/>
    <origin rpy="0 0 0" xyz="0 0.05925 0"/>
    <limit effort="30" lower="-1.5" upper="0.7" velocity="10"/>
    <axis xyz="0 1 0"/>
  </joint>
  <transmission name="transmission_front_left_upperleg">
    <type>transmission_interface/SimpleTransmission</type>
    <joint name="J2">
      <hardwareInterface>hardware_interface/EffortJointInterface</hardwareInterface>
    </joint>
    <actuator name="motor_front_left_upperleg">
      <mechanicalReduction>1</mechanicalReduction>
      <hardwareInterface>hardware_interface/EffortJointInterface</hardwareInterface>
    </actuator>
  </transmission>
  <gazebo reference="link_front_left_upperleg">
    <material>Gazebo/White</material>
    <!-- selfCollide>true</selfCollide -->
    <gravity>true</gravity>
  </gazebo>
  <link name="link_front_left_lowerleg">
    <visual>
      <origin rpy="0 0 0" xyz="0 0 0"/>
      <geometry>
        <mesh filename="package://qd_simulation/robot_description/mesh/left_tibia.dae"/>
      </geometry>
      <material name="blue"/>
    </visual>
    <collision>
      <origin rpy="0 0 0" xyz="0.055 0 0"/>
      <geometry>
        <box size="0.15 0.048 0.028"/>
        <!-- mesh filename="package://qd_simulation/robot_description/mesh/left_tibia.dae"/-->
      </geometry>
    </collision>
    <inertial>
      <mass value="0.10059"/>
      <origin xyz=" 0.025048 -0.002594 0.000523"/>
      <inertia ixx="0.000017" ixy="0.000001" ixz="0.000004" iyy="0.000149" iyz="0.0" izz="0.000158"/>
    </inertial>
  </link>
  <joint name="J3" type="revolute">
    <parent link="link_front_left_upperleg"/>
    <child link="link_front_left_lowerleg"/>
    <origin rpy="0 1.5708 0" xyz="-0.1396 0 -0.01886"/>
    <axis xyz="0 1 0"/>
    <limit effort="30" lower="-1.396" upper="1.745" velocity="10"/>
  </joint>
  <transmission name="transmission_front_left_lowerleg">
    <type>transmission_interface/SimpleTransmission</type>
    <joint name="J3">
      <hardwareInterface>hardware_interface/EffortJointInterface</hardwareInterface>
    </joint>
    <actuator name="motor_front_left_lowerleg">
      <mechanicalReduction>1</mechanicalReduction>
      <hardwareInterface>hardware_interface/EffortJointInterface</hardwareInterface>
    </actuator>
  </transmission>
  <gazebo reference="link_front_left_lowerleg">
    <material>Gazebo/White</material>
    <!-- selfCollide>true</selfCollide -->
    <gravity>true</gravity>
  </gazebo>
  <!-- Paw -->
  <link name="link_front_left_paw">
    <visual>
      <origin rpy="0 0 0" xyz="0 0 0"/>
      <geometry>
        <mesh filename="package://qd_simulation/robot_description/mesh/tpe_tip.dae"/>
      </geometry>
      <material name="green"/>
    </visual>
    <collision>
      <origin rpy="0 0 0" xyz="0 0 0"/>
      <geometry>
        <sphere radius="0.02"/>
        <!-- mesh filename="package://qd_simulation/robot_description/mesh/tpe_tip.dae"/-->
      </geometry>
    </collision>
    <inertial>
      <mass value="0.003"/>
      <inertia ixx="0.00001" ixy="0.0" ixz="0.0" iyy="0.00001" iyz="0.0" izz="0.00001"/>
    </inertial>
  </link>
  <joint name="joint_front_left_paw" type="fixed">
    <parent link="link_front_left_lowerleg"/>
    <child link="link_front_left_paw"/>
    <origin rpy="0 0.698 0" xyz="0.1296 0 0"/>
  </joint>
  <gazebo reference="link_front_left_paw">
    <material>Gazebo/Green</material>
    <!-- selfCollide>true</selfCollide -->
    <gravity>true</gravity>
  </gazebo>
  <link name="link_front_right_hip">
    <visual>
      <origin rpy="0 0 0" xyz="0 0 0"/>
      <geometry>
        <mesh filename="package://qd_simulation/robot_description/mesh/right_hip.dae"/>
      </geometry>
      <material name="red"/>
    </visual>
    <collision>
      <origin rpy="0 0 0" xyz="0.014 -0.04125 0.0147"/>
      <geometry>
        <box size="0.064 0.103 0.0685"/>
        <!-- mesh filename="package://qd_simulation/robot_description/mesh/right_hip.dae"/-->
      </geometry>
    </collision>
    <inertial>
      <mass value="0.1191"/>
      <origin xyz="0.00364 0.0025 0.01974"/>
      <inertia ixx="0.000176" ixy="-0.000004" ixz="-0.000017" iyy="0.000131" iyz="-0.000021" izz="0.000108"/>
    </inertial>
  </link>
  <joint name="J4" type="revolute">
    <parent link="chassis"/>
    <child link="link_front_right_hip"/>
    <origin rpy="0 0 0" xyz="0.12 -0.089 0"/>
    <limit effort="30" lower="-0.785" upper="0.401" velocity="10"/>
    <axis xyz="1 0 0"/>
  </joint>
  <transmission name="transmission_front_right_hip">
    <type>transmission_interface/SimpleTransmission</type>
    <joint name="J4">
      <hardwareInterface>hardware_interface/EffortJointInterface</hardwareInterface>
    </joint>
    <actuator name="motor_front_right_hip">
      <mechanicalReduction>1</mechanicalReduction>
      <hardwareInterface>hardware_interface/EffortJointInterface</hardwareInterface>
    </actuator>
  </transmission>
  <gazebo reference="link_front_right_hip">
    <material>Gazebo/Red</material>
    <!-- selfCollide>true</selfCollide -->
    <gravity>true</gravity>
  </gazebo>
  <link name="link_front_right_upperleg">
    <visual>
      <origin rpy="0 0 0" xyz="0 0 0"/>
      <geometry>
        <mesh filename="package://qd_simulation/robot_description/mesh/right_femur.dae"/>
      </geometry>
      <material name="blue"/>
    </visual>
    <collision>
      <origin rpy="0 0 0" xyz="-0.066 0 -0.008"/>
      <geometry>
        <box size="0.172 0.073 0.046"/>
        <!-- mesh filename="package://qd_simulation/robot_description/mesh/right_femur.dae"/-->
      </geometry>
    </collision>
    <inertial>
      <mass value="0.13118"/>
      <origin xyz="-0.041697 -0.007043 -0.000214"/>
      <inertia ixx="0.000042" ixy="-0.000009" ixz="0.000011" iyy="0.000283" iyz="0.000002" izz="0.000310"/>
    </inertial>
  </link>
  <joint name="J5" type="revolute">
    <parent link="link_front_right_hip"/>
    <child link="link_front_right_upperleg"/>
    <origin rpy="0 0 0" xyz="0 -0.05925 0"/>
    <limit effort="1" lower="-1.5" upper="0.7" velocity="1.0"/>
    <axis xyz="0 1 0"/>
  </joint>
  <transmission name="transmission_front_right_upperleg">
    <type>transmission_interface/SimpleTransmission</type>
    <joint name="J5">
      <hardwareInterface>hardware_interface/EffortJointInterface</hardwareInterface>
    </joint>
    <actuator name="motor_front_right_upperleg">
      <mechanicalReduction>1</mechanicalReduction>
      <hardwareInterface>hardware_interface/EffortJointInterface</hardwareInterface>
    </actuator>
  </transmission>
  <gazebo reference="link_front_right_upperleg">
    <material>Gazebo/White</material>
    <!-- selfCollide>true</selfCollide -->
    <gravity>true</gravity>
  </gazebo>
  <link name="link_front_right_lowerleg">
    <visual>
      <origin rpy="0 0 0" xyz="0 0 0"/>
      <geometry>
        <mesh filename="package://qd_simulation/robot_description/mesh/right_tibia.dae"/>
      </geometry>
      <material name="blue"/>
    </visual>
    <collision>
      <origin rpy="0 0 0" xyz="0.055 0 0"/>
      <geometry>
        <box size="0.15 0.048 0.028"/>
        <!-- mesh filename="package://qd_simulation/robot_description/mesh/right_tibia.dae"/-->
      </geometry>
    </collision>
    <inertial>
      <mass value="0.10059"/>
      <origin xyz=" 0.025048 -0.002594 0.000523"/>
      <inertia ixx="0.000017" ixy="0.000001" ixz="0.000004" iyy="0.000149" iyz="0.0" izz="0.000158"/>
    </inertial>
  </link>
  <joint name="J6" type="revolute">
    <parent link="link_front_right_upperleg"/>
    <child link="link_front_right_lowerleg"/>
    <origin rpy="0 1.5708 0" xyz="-0.1396 0 -0.01886"/>
    <axis xyz="0 1 0"/>
    <limit effort="30" lower="-1.745" upper="1.396" velocity="10"/>
  </joint>
  <transmission name="transmission_front_right_lowerleg">
    <type>transmission_interface/SimpleTransmission</type>
    <joint name="J6">
      <hardwareInterface>hardware_interface/EffortJointInterface</hardwareInterface>
    </joint>
    <actuator name="motor_front_right_lowerleg">
      <mechanicalReduction>1</mechanicalReduction>
      <hardwareInterface>hardware_interface/EffortJointInterface</hardwareInterface>
    </actuator>
  </transmission>
  <gazebo reference="link_front_right_lowerleg">
    <material>Gazebo/White</material>
    <!-- selfCollide>true</selfCollide -->
    <gravity>true</gravity>
  </gazebo>
  <!-- Paw -->
  <link name="link_front_right_paw">
    <visual>
      <origin rpy="0 0 0" xyz="0 0 0"/>
      <geometry>
        <mesh filename="package://qd_simulation/robot_description/mesh/tpe_tip.dae"/>
      </geometry>
      <material name="green"/>
    </visual>
    <collision>
      <origin rpy="0 0 0" xyz="0 0 0"/>
      <geometry>
        <sphere radius="0.02"/>
        <!-- mesh filename="package://qd_simulation/robot_description/mesh/tpe_tip.dae"/-->
      </geometry>
    </collision>
    <inertial>
      <mass value="0.003"/>
      <inertia ixx="0.00001" ixy="0.0" ixz="0.0" iyy="0.00001" iyz="0.0" izz="0.00001"/>
    </inertial>
  </link>
  <joint name="joint_front_right_paw" type="fixed">
    <parent link="link_front_right_lowerleg"/>
    <child link="link_front_right_paw"/>
    <origin rpy="0 0.698 0" xyz="0.1296 0 0"/>
  </joint>
  <gazebo reference="link_front_right_paw">
    <material>Gazebo/Green</material>
    <!-- selfCollide>true</selfCollide -->
    <gravity>true</gravity>
  </gazebo>
  <link name="link_back_left_hip">
    <visual>
      <origin rpy="0 0 0" xyz="0 0 0"/>
      <geometry>
        <mesh filename="package://qd_simulation/robot_description/mesh/left_hip.dae"/>
      </geometry>
      <material name="red"/>
    </visual>
    <collision>
      <origin rpy="0 0 0" xyz="0.014 0.04125 0.0147"/>
      <geometry>
        <box size="0.064 0.103 0.0685"/>
        <!-- mesh filename="package://qd_simulation/robot_description/mesh/left_hip.dae"/-->
      </geometry>
    </collision>
    <inertial>
      <mass value="0.1191"/>
      <origin xyz="0.00364 0.0025 0.01974"/>
      <inertia ixx="0.000176" ixy="-0.000004" ixz="-0.000017" iyy="0.000131" iyz="-0.000021" izz="0.000108"/>
    </inertial>
  </link>
  <joint name="J7" type="revolute">
    <parent link="chassis"/>
    <child link="link_back_left_hip"/>
    <origin rpy="0 0 0" xyz="-0.1486 0.089 0"/>
    <limit effort="30" lower="-0.401" upper="0.785" velocity="10"/>
    <axis xyz="1 0 0"/>
  </joint>
  <transmission name="transmission_back_left_hip">
    <type>transmission_interface/SimpleTransmission</type>
    <joint name="J7">
      <hardwareInterface>hardware_interface/EffortJointInterface</hardwareInterface>
    </joint>
    <actuator name="motor_back_left_hip">
      <mechanicalReduction>1</mechanicalReduction>
      <hardwareInterface>hardware_interface/EffortJointInterface</hardwareInterface>
    </actuator>
  </transmission>
  <gazebo reference="link_back_left_hip">
    <material>Gazebo/Red</material>
    <!-- selfCollide>true</selfCollide -->
    <gravity>true</gravity>
  </gazebo>
  <link name="link_back_left_upperleg">
    <visual>
      <origin rpy="0 0 0" xyz="0 0 0"/>
      <geometry>
        <mesh filename="package://qd_simulation/robot_description/mesh/left_femur.dae"/>
      </geometry>
      <material name="blue"/>
    </visual>
    <collision>
      <origin rpy="0 0 0" xyz="-0.066 0 -0.008"/>
      <geometry>
        <box size="0.172 0.073 0.046"/>
        <!-- mesh filename="package://qd_simulation/robot_description/mesh/left_femur.dae"/-->
      </geometry>
    </collision>
    <inertial>
      <mass value="0.13118"/>
      <origin xyz="-0.041697 -0.007043 -0.000214"/>
      <inertia ixx="0.000042" ixy="-0.000009" ixz="0.000011" iyy="0.000283" iyz="0.000002" izz="0.000310"/>
    </inertial>
  </link>
  <joint name="J8" type="revolute">
    <parent link="link_back_left_hip"/>
    <child link="link_back_left_upperleg"/>
    <origin rpy="0 0 0" xyz="0 0.05925 0"/>
    <limit effort="30" lower="-1.5" upper="0.7" velocity="10"/>
    <axis xyz="0 1 0"/>
  </joint>
  <transmission name="transmission_back_left_upperleg">
    <type>transmission_interface/SimpleTransmission</type>
    <joint name="J8">
      <hardwareInterface>hardware_interface/EffortJointInterface</hardwareInterface>
    </joint>
    <actuator name="motor_back_left_upperleg">
      <mechanicalReduction>1</mechanicalReduction>
      <hardwareInterface>hardware_interface/EffortJointInterface</hardwareInterface>
    </actuator>
  </transmission>
  <gazebo reference="link_back_left_upperleg">
    <material>Gazebo/White</material>
    <!-- selfCollide>true</selfCollide -->
    <gravity>true</gravity>
  </gazebo>
  <link name="link_back_left_lowerleg">
    <visual>
      <origin rpy="0 0 0" xyz="0 0 0"/>
      <geometry>
        <mesh filename="package://qd_simulation/robot_description/mesh/left_tibia.dae"/>
      </geometry>
      <material name="blue"/>
    </visual>
    <collision>
      <origin rpy="0 0 0" xyz="0.055 0 0"/>
      <geometry>
        <box size="0.15 0.048 0.028"/>
        <!-- mesh filename="package://qd_simulation/robot_description/mesh/left_tibia.dae"/-->
      </geometry>
    </collision>
    <inertial>
      <mass value="0.10059"/>
      <origin xyz=" 0.025048 -0.002594 0.000523"/>
      <inertia ixx="0.000017" ixy="0.000001" ixz="0.000004" iyy="0.000149" iyz="0.0" izz="0.000158"/>
    </inertial>
  </link>
  <joint name="J9" type="revolute">
    <parent link="link_back_left_upperleg"/>
    <child link="link_back_left_lowerleg"/>
    <origin rpy="0 1.5708 0" xyz="-0.1396 0 -0.01886"/>
    <axis xyz="0 1 0"/>
    <limit effort="30" lower="-1.396" upper="1.745" velocity="10"/>
  </joint>
  <transmission name="transmission_back_left_lowerleg">
    <type>transmission_interface/SimpleTransmission</type>
    <joint name="J9">
      <hardwareInterface>hardware_interface/EffortJointInterface</hardwareInterface>
    </joint>
    <actuator name="motor_back_left_lowerleg">
      <mechanicalReduction>1</mechanicalReduction>
      <hardwareInterface>hardware_interface/EffortJointInterface</hardwareInterface>
    </actuator>
  </transmission>
  <gazebo reference="link_back_left_lowerleg">
    <material>Gazebo/White</material>
    <!-- selfCollide>true</selfCollide -->
    <gravity>true</gravity>
  </gazebo>
  <!-- Paw -->
  <link name="link_back_left_paw">
    <visual>
      <origin rpy="0 0 0" xyz="0 0 0"/>
      <geometry>
        <mesh filename="package://qd_simulation/robot_description/mesh/tpe_tip.dae"/>
      </geometry>
      <material name="green"/>
    </visual>
    <collision>
      <origin rpy="0 0 0" xyz="0 0 0"/>
      <geometry>
        <sphere radius="0.02"/>
        <!-- mesh filename="package://qd_simulation/robot_description/mesh/tpe_tip.dae"/-->
      </geometry>
    </collision>
    <inertial>
      <mass value="0.003"/>
      <inertia ixx="0.00001" ixy="0.0" ixz="0.0" iyy="0.00001" iyz="0.0" izz="0.00001"/>
    </inertial>
  </link>
  <joint name="joint_back_left_paw" type="fixed">
    <parent link="link_back_left_lowerleg"/>
    <child link="link_back_left_paw"/>
    <origin rpy="0 0.698 0" xyz="0.1296 0 0"/>
  </joint>
  <gazebo reference="link_back_left_paw">
    <material>Gazebo/Green</material>
    <!-- selfCollide>true</selfCollide -->
    <gravity>true</gravity>
  </gazebo>
  <link name="link_back_right_hip">
    <visual>
      <origin rpy="0 0 0" xyz="0 0 0"/>
      <geometry>
        <mesh filename="package://qd_simulation/robot_description/mesh/right_hip.dae"/>
      </geometry>
      <material name="red"/>
    </visual>
    <collision>
      <origin rpy="0 0 0" xyz="0.014 -0.04125 0.0147"/>
      <geometry>
        <box size="0.064 0.103 0.0685"/>
        <!-- mesh filename="package://qd_simulation/robot_description/mesh/right_hip.dae"/-->
      </geometry>
    </collision>
    <inertial>
      <mass value="0.1191"/>
      <origin xyz="0.00364 0.0025 0.01974"/>
      <inertia ixx="0.000176" ixy="-0.000004" ixz="-0.000017" iyy="0.000131" iyz="-0.000021" izz="0.000108"/>
    </inertial>
  </link>
  <joint name="J10" type="revolute">
    <parent link="chassis"/>
    <child link="link_back_right_hip"/>
    <origin rpy="0 0 0" xyz="-0.1486 -0.089 0"/>
    <limit effort="30" lower="-0.785" upper="0.401" velocity="10"/>
    <axis xyz="1 0 0"/>
  </joint>
  <transmission name="transmission_back_right_hip">
    <type>transmission_interface/SimpleTransmission</type>
    <joint name="J10">
      <hardwareInterface>hardware_interface/EffortJointInterface</hardwareInterface>
    </joint>
    <actuator name="motor_back_right_hip">
      <mechanicalReduction>1</mechanicalReduction>
      <hardwareInterface>hardware_interface/EffortJointInterface</hardwareInterface>
    </actuator>
  </transmission>
  <gazebo reference="link_back_right_hip">
    <material>Gazebo/Red</material>
    <!-- selfCollide>true</selfCollide -->
    <gravity>true</gravity>
  </gazebo>
  <link name="link_back_right_upperleg">
    <visual>
      <origin rpy="0 0 0" xyz="0 0 0"/>
      <geometry>
        <mesh filename="package://qd_simulation/robot_description/mesh/right_femur.dae"/>
      </geometry>
      <material name="blue"/>
    </visual>
    <collision>
      <origin rpy="0 0 0" xyz="-0.066 0 -0.008"/>
      <geometry>
        <box size="0.172 0.073 0.046"/>
        <!-- mesh filename="package://qd_simulation/robot_description/mesh/right_femur.dae"/-->
      </geometry>
    </collision>
    <inertial>
      <mass value="0.13118"/>
      <origin xyz="-0.041697 -0.007043 -0.000214"/>
      <inertia ixx="0.000042" ixy="-0.000009" ixz="0.000011" iyy="0.000283" iyz="0.000002" izz="0.000310"/>
    </inertial>
  </link>
  <joint name="J11" type="revolute">
    <parent link="link_back_right_hip"/>
    <child link="link_back_right_upperleg"/>
    <origin rpy="0 0 0" xyz="0 -0.05925 0"/>
    <limit effort="1" lower="-1.5" upper="0.7" velocity="1.0"/>
    <axis xyz="0 1 0"/>
  </joint>
  <transmission name="transmission_back_right_upperleg">
    <type>transmission_interface/SimpleTransmission</type>
    <joint name="J11">
      <hardwareInterface>hardware_interface/EffortJointInterface</hardwareInterface>
    </joint>
    <actuator name="motor_back_right_upperleg">
      <mechanicalReduction>1</mechanicalReduction>
      <hardwareInterface>hardware_interface/EffortJointInterface</hardwareInterface>
    </actuator>
  </transmission>
  <gazebo reference="link_back_right_upperleg">
    <material>Gazebo/White</material>
    <!-- selfCollide>true</selfCollide -->
    <gravity>true</gravity>
  </gazebo>
  <link name="link_back_right_lowerleg">
    <visual>
      <origin rpy="0 0 0" xyz="0 0 0"/>
      <geometry>
        <mesh filename="package://qd_simulation/robot_description/mesh/right_tibia.dae"/>
      </geometry>
      <material name="blue"/>
    </visual>
    <collision>
      <origin rpy="0 0 0" xyz="0.055 0 0"/>
      <geometry>
        <box size="0.15 0.048 0.028"/>
        <!-- mesh filename="package://qd_simulation/robot_description/mesh/right_tibia.dae"/-->
      </geometry>
    </collision>
    <inertial>
      <mass value="0.10059"/>
      <origin xyz=" 0.025048 -0.002594 0.000523"/>
      <inertia ixx="0.000017" ixy="0.000001" ixz="0.000004" iyy="0.000149" iyz="0.0" izz="0.000158"/>
    </inertial>
  </link>
  <joint name="J12" type="revolute">
    <parent link="link_back_right_upperleg"/>
    <child link="link_back_right_lowerleg"/>
    <origin rpy="0 1.5708 0" xyz="-0.1396 0 -0.01886"/>
    <axis xyz="0 1 0"/>
    <limit effort="30" lower="-1.745" upper="1.396" velocity="10"/>
  </joint>
  <transmission name="transmission_back_right_lowerleg">
    <type>transmission_interface/SimpleTransmission</type>
    <joint name="J12">
      <hardwareInterface>hardware_interface/EffortJointInterface</hardwareInterface>
    </joint>
    <actuator name="motor_back_right_lowerleg">
      <mechanicalReduction>1</mechanicalReduction>
      <hardwareInterface>hardware_interface/EffortJointInterface</hardwareInterface>
    </actuator>
  </transmission>
  <gazebo reference="link_back_right_lowerleg">
    <material>Gazebo/White</material>
    <!-- selfCollide>true</selfCollide -->
    <gravity>true</gravity>
  </gazebo>
  <!-- Paw -->
  <link name="link_back_right_paw">
    <visual>
      <origin rpy="0 0 0" xyz="0 0 0"/>
      <geometry>
        <mesh filename="package://qd_simulation/robot_description/mesh/tpe_tip.dae"/>
      </geometry>
      <material name="green"/>
    </visual>
    <collision>
      <origin rpy="0 0 0" xyz="0 0 0"/>
      <geometry>
        <sphere radius="0.02"/>
        <!-- mesh filename="package://qd_simulation/robot_description/mesh/tpe_tip.dae"/-->
      </geometry>
    </collision>
    <inertial>
      <mass value="0.003"/>
      <inertia ixx="0.00001" ixy="0.0" ixz="0.0" iyy="0.00001" iyz="0.0" izz="0.00001"/>
    </inertial>
  </link>
  <joint name="joint_back_right_paw" type="fixed">
    <parent link="link_back_right_lowerleg"/>
    <child link="link_back_right_paw"/>
    <origin rpy="0 0.698 0" xyz="0.1296 0 0"/>
  </joint>
  <gazebo reference="link_back_right_paw">
    <material>Gazebo/Green</material>
    <!-- selfCollide>true</selfCollide -->
    <gravity>true</gravity>
  </gazebo>
</robot>

