<?xml version="1.0" ?>
<!-- =================================================================================== -->
<!-- |    This document was autogenerated by xacro from quadrus.xacro                  | -->
<!-- |    EDITING THIS FILE BY HAND IS NOT RECOMMENDED                                 | -->
<!-- =================================================================================== -->
<robot name="quadrus">
  <material name="black">
    <color rgba="0.0 0.0 0.0 1.0"/>
  </material>
  <material name="blue">
    <color rgba="0.0 0.0 0.8 1.0"/>
  </material>
  <material name="green">
    <color rgba="0.0 0.8 0.0 1.0"/>
  </material>
  <material name="grey">
    <color rgba="0.2 0.2 0.2 1.0"/>
  </material>
  <material name="orange">
    <color rgba="1.0 0.4235294117647059 0.0392156862745098 1.0"/>
  </material>
  <material name="brown">
    <color rgba="0.8705882352941177 0.8117647058823529 0.7647058823529411 1.0"/>
  </material>
  <material name="red">
    <color rgba="0.8 0.0 0.0 1.0"/>
  </material>
  <material name="white">
    <color rgba="1.0 1.0 1.0 1.0"/>
  </material>
  <!-- ros_control plugin -->
  <gazebo>
    <plugin filename="libgazebo_ros_control.so" name="gazebo_ros_control">
      <robotNamespace>/quadrus</robotNamespace>
      <robotSimType>gazebo_ros_control/DefaultRobotHWSim</robotSimType>
    </plugin>
  </gazebo>
  <gazebo reference="base_link">
    <material>Gazebo/Blue</material>
    <pose>0 0 1 0 0 0 </pose>
  </gazebo>
  <!-- Used for fixing robot to Gazebo 'base_link' -->
  <link name="world"/>
  <joint name="fixed" type="fixed">
    <parent link="world"/>
    <child link="base_link"/>
    <origin xyz="0 0 1"/>
  </joint>
  <link name="base_link">
    <visual>
      <origin rpy="0 0 0" xyz="0 0 0"/>
      <geometry>
        <box size="0.4172 0.116 0.03035"/>
      </geometry>
      <material name="blue"/>
    </visual>
    <visual>
      <origin rpy="0 0 0" xyz="0 0 0"/>
      <geometry>
        <box size="0.2 0.2 0.03035"/>
      </geometry>
      <material name="blue"/>
    </visual>
    <collision>
      <origin rpy="0 0 0" xyz="0 0 0"/>
      <geometry>
        <box size="0.4172 0.116 0.03035"/>
      </geometry>
    </collision>
    <inertial>
      <mass value="0.500"/>
      <inertia ixx="0.00093" ixy="0.0" ixz="0.0" iyy="0.00458" iyz="0.0" izz="0.00540"/>
    </inertial>
  </link>
  <link name="link_front_left_hip">
    <visual>
      <origin rpy="0 0 0" xyz="0 0 0"/>
      <geometry>
        <box size="0.060 0.035 0.078"/>
      </geometry>
      <material name="red"/>
    </visual>
    <collision>
      <origin rpy="0 0 0" xyz="0 0 0"/>
      <geometry>
        <box size="0.060 0.035 0.078"/>
      </geometry>
    </collision>
    <inertial>
      <mass value="0.332"/>
      <inertia ixx="0.00109" ixy="0.0" ixz="-0.00004" iyy="0.00146" iyz="-0.00039" izz="0.00066"/>
    </inertial>
  </link>
  <joint name="J1" type="continuous">
    <parent link="base_link"/>
    <child link="link_front_left_hip"/>
    <origin rpy="0 0 0" xyz="0.12000000000000002 0.079 0"/>
    <axis xyz="1 0 0"/>
  </joint>
  <transmission name="transmission_front_left_hip">
    <type>transmission_interface/SimpleTransmission</type>
    <joint name="J1">
      <hardwareInterface>hardware_interface/EffortJointInterface</hardwareInterface>
    </joint>
    <actuator name="motor_front_left_hip">
      <mechanicalReduction>1</mechanicalReduction>
      <hardwareInterface>hardware_interface/EffortJointInterface</hardwareInterface>
    </actuator>
  </transmission>
  <gazebo reference="link_front_left_hip">
    <material>Gazebo/Red</material>
  </gazebo>
  <link name="link_front_left_upperleg">
    <visual>
      <origin rpy="0 0 0" xyz="-0.07 0 0"/>
      <geometry>
        <box size="0.17 0.0365 0.026"/>
      </geometry>
      <material name="blue"/>
    </visual>
    <collision>
      <origin rpy="0 0 0" xyz="-0.07 0 0"/>
      <geometry>
        <box size="0.17  0.0365 0.026"/>
      </geometry>
    </collision>
    <inertial>
      <mass value="0.32114"/>
      <inertia ixx="0.00014" ixy="0.00001" ixz="0.00002" iyy="0.00207" iyz="0.0" izz="0.00215"/>
    </inertial>
  </link>
  <joint name="J2" type="continuous">
    <parent link="link_front_left_hip"/>
    <child link="link_front_left_upperleg"/>
    <origin rpy="0 0 0" xyz="0 0.05755 0"/>
    <axis xyz="0 1 0"/>
  </joint>
  <transmission name="transmission_front_left_upperleg">
    <type>transmission_interface/SimpleTransmission</type>
    <joint name="J2">
      <hardwareInterface>hardware_interface/EffortJointInterface</hardwareInterface>
    </joint>
    <actuator name="motor_front_left_upperleg">
      <mechanicalReduction>1</mechanicalReduction>
      <hardwareInterface>hardware_interface/EffortJointInterface</hardwareInterface>
    </actuator>
  </transmission>
  <gazebo reference="link_front_left_upperleg">
    <material>Gazebo/White</material>
  </gazebo>
  <link name="link_front_left_lowerleg">
    <visual>
      <origin rpy="0 0 0" xyz="0.075 0 0"/>
      <geometry>
        <box size="0.17833 0.02 0.03"/>
      </geometry>
      <material name="blue"/>
    </visual>
    <collision>
      <origin rpy="0 0 0" xyz="0.075 0 0"/>
      <geometry>
        <box size="0.17833 0.02 0.03"/>
      </geometry>
    </collision>
    <inertial>
      <mass value="0.20407"/>
      <inertia ixx="0.00005" ixy="0.00008" ixz="0.0" iyy="0.00121" iyz="0.0" izz="0.00123"/>
    </inertial>
  </link>
  <joint name="J3" type="continuous">
    <parent link="link_front_left_upperleg"/>
    <child link="link_front_left_lowerleg"/>
    <origin rpy="0 1.5708 0" xyz="-0.15 0 -0.0156"/>
    <axis xyz="0 1 0"/>
  </joint>
  <transmission name="transmission_front_left_lowerleg">
    <type>transmission_interface/SimpleTransmission</type>
    <joint name="J3">
      <hardwareInterface>hardware_interface/EffortJointInterface</hardwareInterface>
    </joint>
    <actuator name="motor_front_left_lowerleg">
      <mechanicalReduction>1</mechanicalReduction>
      <hardwareInterface>hardware_interface/EffortJointInterface</hardwareInterface>
    </actuator>
  </transmission>
  <gazebo reference="link_front_left_lowerleg">
    <material>Gazebo/White</material>
  </gazebo>
  <!-- Paw -->
  <link name="link_front_left_paw">
    <visual>
      <origin rpy="0 0 0" xyz="0 0 0"/>
      <geometry>
        <sphere radius="0.02"/>
      </geometry>
      <material name="green"/>
    </visual>
    <collision>
      <origin rpy="0 0 0" xyz="0 0 0"/>
      <geometry>
        <sphere radius="0.02"/>
      </geometry>
    </collision>
    <inertial>
      <mass value="0.0"/>
      <inertia ixx="0.0" ixy="0.0" ixz="0.0" iyy="0.0" iyz="0.0" izz="0.0"/>
    </inertial>
  </link>
  <joint name="joint_front_left_paw" type="fixed">
    <parent link="link_front_left_lowerleg"/>
    <child link="link_front_left_paw"/>
    <origin rpy="0 0 0" xyz="0.15 0 0"/>
  </joint>
  <gazebo reference="link_front_left_paw">
    <material>Gazebo/Green</material>
  </gazebo>
  <link name="link_front_right_hip">
    <visual>
      <origin rpy="0 0 0" xyz="0 0 0"/>
      <geometry>
        <box size="0.060 0.035 0.078"/>
      </geometry>
      <material name="red"/>
    </visual>
    <collision>
      <origin rpy="0 0 0" xyz="0 0 0"/>
      <geometry>
        <box size="0.060 0.035 0.078"/>
      </geometry>
    </collision>
    <inertial>
      <mass value="0.332"/>
      <inertia ixx="0.00109" ixy="0.0" ixz="-0.00004" iyy="0.00146" iyz="-0.00039" izz="0.00066"/>
    </inertial>
  </link>
  <joint name="J4" type="continuous">
    <parent link="base_link"/>
    <child link="link_front_right_hip"/>
    <origin rpy="0 0 0" xyz="0.12000000000000002 -0.079 0"/>
    <axis xyz="1 0 0"/>
  </joint>
  <transmission name="transmission_front_right_hip">
    <type>transmission_interface/SimpleTransmission</type>
    <joint name="J4">
      <hardwareInterface>hardware_interface/EffortJointInterface</hardwareInterface>
    </joint>
    <actuator name="motor_front_right_hip">
      <mechanicalReduction>1</mechanicalReduction>
      <hardwareInterface>hardware_interface/EffortJointInterface</hardwareInterface>
    </actuator>
  </transmission>
  <gazebo reference="link_front_right_hip">
    <material>Gazebo/Red</material>
  </gazebo>
  <link name="link_front_right_upperleg">
    <visual>
      <origin rpy="0 0 0" xyz="-0.07 0 0"/>
      <geometry>
        <box size="0.17 0.0365 0.026"/>
      </geometry>
      <material name="blue"/>
    </visual>
    <collision>
      <origin rpy="0 0 0" xyz="-0.07 0 0"/>
      <geometry>
        <box size="0.17  0.0365 0.026"/>
      </geometry>
    </collision>
    <inertial>
      <mass value="0.32114"/>
      <inertia ixx="0.00014" ixy="0.00001" ixz="0.00002" iyy="0.00207" iyz="0.0" izz="0.00215"/>
    </inertial>
  </link>
  <joint name="J5" type="continuous">
    <parent link="link_front_right_hip"/>
    <child link="link_front_right_upperleg"/>
    <origin rpy="0 0 0" xyz="0 -0.05755 0"/>
    <axis xyz="0 1 0"/>
  </joint>
  <transmission name="transmission_front_right_upperleg">
    <type>transmission_interface/SimpleTransmission</type>
    <joint name="J5">
      <hardwareInterface>hardware_interface/EffortJointInterface</hardwareInterface>
    </joint>
    <actuator name="motor_front_right_upperleg">
      <mechanicalReduction>1</mechanicalReduction>
      <hardwareInterface>hardware_interface/EffortJointInterface</hardwareInterface>
    </actuator>
  </transmission>
  <gazebo reference="link_front_right_upperleg">
    <material>Gazebo/White</material>
  </gazebo>
  <link name="link_front_right_lowerleg">
    <visual>
      <origin rpy="0 0 0" xyz="0.075 0 0"/>
      <geometry>
        <box size="0.17833 0.02 0.03"/>
      </geometry>
      <material name="blue"/>
    </visual>
    <collision>
      <origin rpy="0 0 0" xyz="0.075 0 0"/>
      <geometry>
        <box size="0.17833 0.02 0.03"/>
      </geometry>
    </collision>
    <inertial>
      <mass value="0.20407"/>
      <inertia ixx="0.00005" ixy="0.00008" ixz="0.0" iyy="0.00121" iyz="0.0" izz="0.00123"/>
    </inertial>
  </link>
  <joint name="J6" type="continuous">
    <parent link="link_front_right_upperleg"/>
    <child link="link_front_right_lowerleg"/>
    <origin rpy="0 1.5708 0" xyz="-0.15 0 -0.0156"/>
    <axis xyz="0 1 0"/>
  </joint>
  <transmission name="transmission_front_right_lowerleg">
    <type>transmission_interface/SimpleTransmission</type>
    <joint name="J6">
      <hardwareInterface>hardware_interface/EffortJointInterface</hardwareInterface>
    </joint>
    <actuator name="motor_front_right_lowerleg">
      <mechanicalReduction>1</mechanicalReduction>
      <hardwareInterface>hardware_interface/EffortJointInterface</hardwareInterface>
    </actuator>
  </transmission>
  <gazebo reference="link_front_right_lowerleg">
    <material>Gazebo/White</material>
  </gazebo>
  <!-- Paw -->
  <link name="link_front_right_paw">
    <visual>
      <origin rpy="0 0 0" xyz="0 0 0"/>
      <geometry>
        <sphere radius="0.02"/>
      </geometry>
      <material name="green"/>
    </visual>
    <collision>
      <origin rpy="0 0 0" xyz="0 0 0"/>
      <geometry>
        <sphere radius="0.02"/>
      </geometry>
    </collision>
    <inertial>
      <mass value="0.0"/>
      <inertia ixx="0.0" ixy="0.0" ixz="0.0" iyy="0.0" iyz="0.0" izz="0.0"/>
    </inertial>
  </link>
  <joint name="joint_front_right_paw" type="fixed">
    <parent link="link_front_right_lowerleg"/>
    <child link="link_front_right_paw"/>
    <origin rpy="0 0 0" xyz="0.15 0 0"/>
  </joint>
  <gazebo reference="link_front_right_paw">
    <material>Gazebo/Green</material>
  </gazebo>
  <link name="link_back_left_hip">
    <visual>
      <origin rpy="0 0 0" xyz="0 0 0"/>
      <geometry>
        <box size="0.060 0.035 0.078"/>
      </geometry>
      <material name="red"/>
    </visual>
    <collision>
      <origin rpy="0 0 0" xyz="0 0 0"/>
      <geometry>
        <box size="0.060 0.035 0.078"/>
      </geometry>
    </collision>
    <inertial>
      <mass value="0.332"/>
      <inertia ixx="0.00109" ixy="0.0" ixz="-0.00004" iyy="0.00146" iyz="-0.00039" izz="0.00066"/>
    </inertial>
  </link>
  <joint name="J7" type="continuous">
    <parent link="base_link"/>
    <child link="link_back_left_hip"/>
    <origin rpy="0 0 0" xyz="-0.148 0.079 0"/>
    <axis xyz="1 0 0"/>
  </joint>
  <transmission name="transmission_back_left_hip">
    <type>transmission_interface/SimpleTransmission</type>
    <joint name="J7">
      <hardwareInterface>hardware_interface/EffortJointInterface</hardwareInterface>
    </joint>
    <actuator name="motor_back_left_hip">
      <mechanicalReduction>1</mechanicalReduction>
      <hardwareInterface>hardware_interface/EffortJointInterface</hardwareInterface>
    </actuator>
  </transmission>
  <gazebo reference="link_back_left_hip">
    <material>Gazebo/Red</material>
  </gazebo>
  <link name="link_back_left_upperleg">
    <visual>
      <origin rpy="0 0 0" xyz="-0.07 0 0"/>
      <geometry>
        <box size="0.17 0.0365 0.026"/>
      </geometry>
      <material name="blue"/>
    </visual>
    <collision>
      <origin rpy="0 0 0" xyz="-0.07 0 0"/>
      <geometry>
        <box size="0.17  0.0365 0.026"/>
      </geometry>
    </collision>
    <inertial>
      <mass value="0.32114"/>
      <inertia ixx="0.00014" ixy="0.00001" ixz="0.00002" iyy="0.00207" iyz="0.0" izz="0.00215"/>
    </inertial>
  </link>
  <joint name="J8" type="continuous">
    <parent link="link_back_left_hip"/>
    <child link="link_back_left_upperleg"/>
    <origin rpy="0 0 0" xyz="0 0.05755 0"/>
    <axis xyz="0 1 0"/>
  </joint>
  <transmission name="transmission_back_left_upperleg">
    <type>transmission_interface/SimpleTransmission</type>
    <joint name="J8">
      <hardwareInterface>hardware_interface/EffortJointInterface</hardwareInterface>
    </joint>
    <actuator name="motor_back_left_upperleg">
      <mechanicalReduction>1</mechanicalReduction>
      <hardwareInterface>hardware_interface/EffortJointInterface</hardwareInterface>
    </actuator>
  </transmission>
  <gazebo reference="link_back_left_upperleg">
    <material>Gazebo/White</material>
  </gazebo>
  <link name="link_back_left_lowerleg">
    <visual>
      <origin rpy="0 0 0" xyz="0.075 0 0"/>
      <geometry>
        <box size="0.17833 0.02 0.03"/>
      </geometry>
      <material name="blue"/>
    </visual>
    <collision>
      <origin rpy="0 0 0" xyz="0.075 0 0"/>
      <geometry>
        <box size="0.17833 0.02 0.03"/>
      </geometry>
    </collision>
    <inertial>
      <mass value="0.20407"/>
      <inertia ixx="0.00005" ixy="0.00008" ixz="0.0" iyy="0.00121" iyz="0.0" izz="0.00123"/>
    </inertial>
  </link>
  <joint name="J9" type="continuous">
    <parent link="link_back_left_upperleg"/>
    <child link="link_back_left_lowerleg"/>
    <origin rpy="0 1.5708 0" xyz="-0.15 0 -0.0156"/>
    <axis xyz="0 1 0"/>
  </joint>
  <transmission name="transmission_back_left_lowerleg">
    <type>transmission_interface/SimpleTransmission</type>
    <joint name="J9">
      <hardwareInterface>hardware_interface/EffortJointInterface</hardwareInterface>
    </joint>
    <actuator name="motor_back_left_lowerleg">
      <mechanicalReduction>1</mechanicalReduction>
      <hardwareInterface>hardware_interface/EffortJointInterface</hardwareInterface>
    </actuator>
  </transmission>
  <gazebo reference="link_back_left_lowerleg">
    <material>Gazebo/White</material>
  </gazebo>
  <!-- Paw -->
  <link name="link_back_left_paw">
    <visual>
      <origin rpy="0 0 0" xyz="0 0 0"/>
      <geometry>
        <sphere radius="0.02"/>
      </geometry>
      <material name="green"/>
    </visual>
    <collision>
      <origin rpy="0 0 0" xyz="0 0 0"/>
      <geometry>
        <sphere radius="0.02"/>
      </geometry>
    </collision>
    <inertial>
      <mass value="0.0"/>
      <inertia ixx="0.0" ixy="0.0" ixz="0.0" iyy="0.0" iyz="0.0" izz="0.0"/>
    </inertial>
  </link>
  <joint name="joint_back_left_paw" type="fixed">
    <parent link="link_back_left_lowerleg"/>
    <child link="link_back_left_paw"/>
    <origin rpy="0 0 0" xyz="0.15 0 0"/>
  </joint>
  <gazebo reference="link_back_left_paw">
    <material>Gazebo/Green</material>
  </gazebo>
  <link name="link_back_right_hip">
    <visual>
      <origin rpy="0 0 0" xyz="0 0 0"/>
      <geometry>
        <box size="0.060 0.035 0.078"/>
      </geometry>
      <material name="red"/>
    </visual>
    <collision>
      <origin rpy="0 0 0" xyz="0 0 0"/>
      <geometry>
        <box size="0.060 0.035 0.078"/>
      </geometry>
    </collision>
    <inertial>
      <mass value="0.332"/>
      <inertia ixx="0.00109" ixy="0.0" ixz="-0.00004" iyy="0.00146" iyz="-0.00039" izz="0.00066"/>
    </inertial>
  </link>
  <joint name="J10" type="continuous">
    <parent link="base_link"/>
    <child link="link_back_right_hip"/>
    <origin rpy="0 0 0" xyz="-0.148 -0.079 0"/>
    <axis xyz="1 0 0"/>
  </joint>
  <transmission name="transmission_back_right_hip">
    <type>transmission_interface/SimpleTransmission</type>
    <joint name="J10">
      <hardwareInterface>hardware_interface/EffortJointInterface</hardwareInterface>
    </joint>
    <actuator name="motor_back_right_hip">
      <mechanicalReduction>1</mechanicalReduction>
      <hardwareInterface>hardware_interface/EffortJointInterface</hardwareInterface>
    </actuator>
  </transmission>
  <gazebo reference="link_back_right_hip">
    <material>Gazebo/Red</material>
  </gazebo>
  <link name="link_back_right_upperleg">
    <visual>
      <origin rpy="0 0 0" xyz="-0.07 0 0"/>
      <geometry>
        <box size="0.17 0.0365 0.026"/>
      </geometry>
      <material name="blue"/>
    </visual>
    <collision>
      <origin rpy="0 0 0" xyz="-0.07 0 0"/>
      <geometry>
        <box size="0.17  0.0365 0.026"/>
      </geometry>
    </collision>
    <inertial>
      <mass value="0.32114"/>
      <inertia ixx="0.00014" ixy="0.00001" ixz="0.00002" iyy="0.00207" iyz="0.0" izz="0.00215"/>
    </inertial>
  </link>
  <joint name="J11" type="continuous">
    <parent link="link_back_right_hip"/>
    <child link="link_back_right_upperleg"/>
    <origin rpy="0 0 0" xyz="0 -0.05755 0"/>
    <axis xyz="0 1 0"/>
  </joint>
  <transmission name="transmission_back_right_upperleg">
    <type>transmission_interface/SimpleTransmission</type>
    <joint name="J11">
      <hardwareInterface>hardware_interface/EffortJointInterface</hardwareInterface>
    </joint>
    <actuator name="motor_back_right_upperleg">
      <mechanicalReduction>1</mechanicalReduction>
      <hardwareInterface>hardware_interface/EffortJointInterface</hardwareInterface>
    </actuator>
  </transmission>
  <gazebo reference="link_back_right_upperleg">
    <material>Gazebo/White</material>
  </gazebo>
  <link name="link_back_right_lowerleg">
    <visual>
      <origin rpy="0 0 0" xyz="0.075 0 0"/>
      <geometry>
        <box size="0.17833 0.02 0.03"/>
      </geometry>
      <material name="blue"/>
    </visual>
    <collision>
      <origin rpy="0 0 0" xyz="0.075 0 0"/>
      <geometry>
        <box size="0.17833 0.02 0.03"/>
      </geometry>
    </collision>
    <inertial>
      <mass value="0.20407"/>
      <inertia ixx="0.00005" ixy="0.00008" ixz="0.0" iyy="0.00121" iyz="0.0" izz="0.00123"/>
    </inertial>
  </link>
  <joint name="J12" type="continuous">
    <parent link="link_back_right_upperleg"/>
    <child link="link_back_right_lowerleg"/>
    <origin rpy="0 1.5708 0" xyz="-0.15 0 -0.0156"/>
    <axis xyz="0 1 0"/>
  </joint>
  <transmission name="transmission_back_right_lowerleg">
    <type>transmission_interface/SimpleTransmission</type>
    <joint name="J12">
      <hardwareInterface>hardware_interface/EffortJointInterface</hardwareInterface>
    </joint>
    <actuator name="motor_back_right_lowerleg">
      <mechanicalReduction>1</mechanicalReduction>
      <hardwareInterface>hardware_interface/EffortJointInterface</hardwareInterface>
    </actuator>
  </transmission>
  <gazebo reference="link_back_right_lowerleg">
    <material>Gazebo/White</material>
  </gazebo>
  <!-- Paw -->
  <link name="link_back_right_paw">
    <visual>
      <origin rpy="0 0 0" xyz="0 0 0"/>
      <geometry>
        <sphere radius="0.02"/>
      </geometry>
      <material name="green"/>
    </visual>
    <collision>
      <origin rpy="0 0 0" xyz="0 0 0"/>
      <geometry>
        <sphere radius="0.02"/>
      </geometry>
    </collision>
    <inertial>
      <mass value="0.0"/>
      <inertia ixx="0.0" ixy="0.0" ixz="0.0" iyy="0.0" iyz="0.0" izz="0.0"/>
    </inertial>
  </link>
  <joint name="joint_back_right_paw" type="fixed">
    <parent link="link_back_right_lowerleg"/>
    <child link="link_back_right_paw"/>
    <origin rpy="0 0 0" xyz="0.15 0 0"/>
  </joint>
  <gazebo reference="link_back_right_paw">
    <material>Gazebo/Green</material>
  </gazebo>
</robot>

